2019-01-10 13:08:34,830 ERROR: Exception on /reset_password_request [POST] [in /Users/clu/Development/learn/learn-flask/simple-flask-heroku/venv/lib/python3.6/site-packages/flask/app.py:1761]
Traceback (most recent call last):
  File "/Users/clu/Development/learn/learn-flask/simple-flask-heroku/venv/lib/python3.6/site-packages/flask/app.py", line 2292, in wsgi_app
    response = self.full_dispatch_request()
  File "/Users/clu/Development/learn/learn-flask/simple-flask-heroku/venv/lib/python3.6/site-packages/flask/app.py", line 1815, in full_dispatch_request
    rv = self.handle_user_exception(e)
  File "/Users/clu/Development/learn/learn-flask/simple-flask-heroku/venv/lib/python3.6/site-packages/flask/app.py", line 1718, in handle_user_exception
    reraise(exc_type, exc_value, tb)
  File "/Users/clu/Development/learn/learn-flask/simple-flask-heroku/venv/lib/python3.6/site-packages/flask/_compat.py", line 35, in reraise
    raise value
  File "/Users/clu/Development/learn/learn-flask/simple-flask-heroku/venv/lib/python3.6/site-packages/flask/app.py", line 1813, in full_dispatch_request
    rv = self.dispatch_request()
  File "/Users/clu/Development/learn/learn-flask/simple-flask-heroku/venv/lib/python3.6/site-packages/flask/app.py", line 1799, in dispatch_request
    return self.view_functions[rule.endpoint](**req.view_args)
  File "/Users/clu/Development/learn/learn-flask/simple-flask-heroku/blogApp/routes.py", line 180, in reset_password_request
    send_password_reset_email(user)
  File "/Users/clu/Development/learn/learn-flask/simple-flask-heroku/blogApp/email.py", line 21, in send_password_reset_email
    user=user, token=token))
  File "/Users/clu/Development/learn/learn-flask/simple-flask-heroku/blogApp/email.py", line 9, in send_email
    mail.send(msg)
  File "/Users/clu/Development/learn/learn-flask/simple-flask-heroku/venv/lib/python3.6/site-packages/flask_mail.py", line 491, in send
    with self.connect() as connection:
  File "/Users/clu/Development/learn/learn-flask/simple-flask-heroku/venv/lib/python3.6/site-packages/flask_mail.py", line 144, in __enter__
    self.host = self.configure_host()
  File "/Users/clu/Development/learn/learn-flask/simple-flask-heroku/venv/lib/python3.6/site-packages/flask_mail.py", line 165, in configure_host
    host.login(self.mail.username, self.mail.password)
  File "/anaconda3/lib/python3.6/smtplib.py", line 730, in login
    raise last_exception
  File "/anaconda3/lib/python3.6/smtplib.py", line 721, in login
    initial_response_ok=initial_response_ok)
  File "/anaconda3/lib/python3.6/smtplib.py", line 642, in auth
    raise SMTPAuthenticationError(code, resp)
smtplib.SMTPAuthenticationError: (535, b'5.7.8 Username and Password not accepted. Learn more at\n5.7.8  https://support.google.com/mail/?p=BadCredentials m81sm9129114itb.43 - gsmtp')
2019-01-10 13:25:58,007 INFO: Microblog startup [in /Users/clu/Development/learn/learn-flask/simple-flask-heroku/blogApp/__init__.py:49]
2019-01-10 13:26:38,507 ERROR: Exception on /reset_password_request [POST] [in /Users/clu/Development/learn/learn-flask/simple-flask-heroku/venv/lib/python3.6/site-packages/flask/app.py:1761]
Traceback (most recent call last):
  File "/Users/clu/Development/learn/learn-flask/simple-flask-heroku/venv/lib/python3.6/site-packages/flask/app.py", line 2292, in wsgi_app
    response = self.full_dispatch_request()
  File "/Users/clu/Development/learn/learn-flask/simple-flask-heroku/venv/lib/python3.6/site-packages/flask/app.py", line 1815, in full_dispatch_request
    rv = self.handle_user_exception(e)
  File "/Users/clu/Development/learn/learn-flask/simple-flask-heroku/venv/lib/python3.6/site-packages/flask/app.py", line 1718, in handle_user_exception
    reraise(exc_type, exc_value, tb)
  File "/Users/clu/Development/learn/learn-flask/simple-flask-heroku/venv/lib/python3.6/site-packages/flask/_compat.py", line 35, in reraise
    raise value
  File "/Users/clu/Development/learn/learn-flask/simple-flask-heroku/venv/lib/python3.6/site-packages/flask/app.py", line 1813, in full_dispatch_request
    rv = self.dispatch_request()
  File "/Users/clu/Development/learn/learn-flask/simple-flask-heroku/venv/lib/python3.6/site-packages/flask/app.py", line 1799, in dispatch_request
    return self.view_functions[rule.endpoint](**req.view_args)
  File "/Users/clu/Development/learn/learn-flask/simple-flask-heroku/blogApp/routes.py", line 180, in reset_password_request
    send_password_reset_email(user)
  File "/Users/clu/Development/learn/learn-flask/simple-flask-heroku/blogApp/email.py", line 21, in send_password_reset_email
    user=user, token=token))
  File "/Users/clu/Development/learn/learn-flask/simple-flask-heroku/blogApp/email.py", line 9, in send_email
    mail.send(msg)
  File "/Users/clu/Development/learn/learn-flask/simple-flask-heroku/venv/lib/python3.6/site-packages/flask_mail.py", line 491, in send
    with self.connect() as connection:
  File "/Users/clu/Development/learn/learn-flask/simple-flask-heroku/venv/lib/python3.6/site-packages/flask_mail.py", line 144, in __enter__
    self.host = self.configure_host()
  File "/Users/clu/Development/learn/learn-flask/simple-flask-heroku/venv/lib/python3.6/site-packages/flask_mail.py", line 165, in configure_host
    host.login(self.mail.username, self.mail.password)
  File "/anaconda3/lib/python3.6/smtplib.py", line 730, in login
    raise last_exception
  File "/anaconda3/lib/python3.6/smtplib.py", line 721, in login
    initial_response_ok=initial_response_ok)
  File "/anaconda3/lib/python3.6/smtplib.py", line 642, in auth
    raise SMTPAuthenticationError(code, resp)
smtplib.SMTPAuthenticationError: (535, b'5.7.8 Username and Password not accepted. Learn more at\n5.7.8  https://support.google.com/mail/?p=BadCredentials y23sm3125103ita.1 - gsmtp')
2019-01-10 13:28:50,035 INFO: Microblog startup [in /Users/clu/Development/learn/learn-flask/simple-flask-heroku/blogApp/__init__.py:49]
2019-01-10 14:30:00,225 INFO: Microblog startup [in /Users/clu/Development/learn/learn-flask/simple-flask-heroku/blogApp/__init__.py:51]
