2019-01-10 13:04:26,173 ERROR: Exception on /reset_password_request [POST] [in /Users/clu/Development/learn/learn-flask/simple-flask-heroku/venv/lib/python3.6/site-packages/flask/app.py:1761]
Traceback (most recent call last):
  File "/Users/clu/Development/learn/learn-flask/simple-flask-heroku/venv/lib/python3.6/site-packages/flask/app.py", line 2292, in wsgi_app
    response = self.full_dispatch_request()
  File "/Users/clu/Development/learn/learn-flask/simple-flask-heroku/venv/lib/python3.6/site-packages/flask/app.py", line 1815, in full_dispatch_request
    rv = self.handle_user_exception(e)
  File "/Users/clu/Development/learn/learn-flask/simple-flask-heroku/venv/lib/python3.6/site-packages/flask/app.py", line 1718, in handle_user_exception
    reraise(exc_type, exc_value, tb)
  File "/Users/clu/Development/learn/learn-flask/simple-flask-heroku/venv/lib/python3.6/site-packages/flask/_compat.py", line 35, in reraise
    raise value
  File "/Users/clu/Development/learn/learn-flask/simple-flask-heroku/venv/lib/python3.6/site-packages/flask/app.py", line 1813, in full_dispatch_request
    rv = self.dispatch_request()
  File "/Users/clu/Development/learn/learn-flask/simple-flask-heroku/venv/lib/python3.6/site-packages/flask/app.py", line 1799, in dispatch_request
    return self.view_functions[rule.endpoint](**req.view_args)
  File "/Users/clu/Development/learn/learn-flask/simple-flask-heroku/blogApp/routes.py", line 179, in reset_password_request
    send_password_reset_email(user)
  File "/Users/clu/Development/learn/learn-flask/simple-flask-heroku/blogApp/email.py", line 14, in send_password_reset_email
    token = user.get_reset_password_token()
  File "/Users/clu/Development/learn/learn-flask/simple-flask-heroku/blogApp/models.py", line 90, in get_reset_password_token
    return jwt.encode({'reset_password': self.id, 'exp': time() + expires_in}, app.config['SECRET_KEY'], algorithm='HS256').decode('utf-8')
NameError: name 'time' is not defined
2019-01-10 13:04:45,322 INFO: Microblog startup [in /Users/clu/Development/learn/learn-flask/simple-flask-heroku/blogApp/__init__.py:49]
2019-01-10 13:04:53,667 ERROR: Exception on /reset_password_request [POST] [in /Users/clu/Development/learn/learn-flask/simple-flask-heroku/venv/lib/python3.6/site-packages/flask/app.py:1761]
Traceback (most recent call last):
  File "/Users/clu/Development/learn/learn-flask/simple-flask-heroku/venv/lib/python3.6/site-packages/flask/app.py", line 2292, in wsgi_app
    response = self.full_dispatch_request()
  File "/Users/clu/Development/learn/learn-flask/simple-flask-heroku/venv/lib/python3.6/site-packages/flask/app.py", line 1815, in full_dispatch_request
    rv = self.handle_user_exception(e)
  File "/Users/clu/Development/learn/learn-flask/simple-flask-heroku/venv/lib/python3.6/site-packages/flask/app.py", line 1718, in handle_user_exception
    reraise(exc_type, exc_value, tb)
  File "/Users/clu/Development/learn/learn-flask/simple-flask-heroku/venv/lib/python3.6/site-packages/flask/_compat.py", line 35, in reraise
    raise value
  File "/Users/clu/Development/learn/learn-flask/simple-flask-heroku/venv/lib/python3.6/site-packages/flask/app.py", line 1813, in full_dispatch_request
    rv = self.dispatch_request()
  File "/Users/clu/Development/learn/learn-flask/simple-flask-heroku/venv/lib/python3.6/site-packages/flask/app.py", line 1799, in dispatch_request
    return self.view_functions[rule.endpoint](**req.view_args)
  File "/Users/clu/Development/learn/learn-flask/simple-flask-heroku/blogApp/routes.py", line 179, in reset_password_request
    send_password_reset_email(user)
  File "/Users/clu/Development/learn/learn-flask/simple-flask-heroku/blogApp/email.py", line 19, in send_password_reset_email
    user=user, token=token),
  File "/Users/clu/Development/learn/learn-flask/simple-flask-heroku/venv/lib/python3.6/site-packages/flask/templating.py", line 135, in render_template
    context, ctx.app)
  File "/Users/clu/Development/learn/learn-flask/simple-flask-heroku/venv/lib/python3.6/site-packages/flask/templating.py", line 117, in _render
    rv = template.render(context)
  File "/Users/clu/Development/learn/learn-flask/simple-flask-heroku/venv/lib/python3.6/site-packages/jinja2/asyncsupport.py", line 76, in render
    return original_render(self, *args, **kwargs)
  File "/Users/clu/Development/learn/learn-flask/simple-flask-heroku/venv/lib/python3.6/site-packages/jinja2/environment.py", line 1008, in render
    return self.environment.handle_exception(exc_info, True)
  File "/Users/clu/Development/learn/learn-flask/simple-flask-heroku/venv/lib/python3.6/site-packages/jinja2/environment.py", line 780, in handle_exception
    reraise(exc_type, exc_value, tb)
  File "/Users/clu/Development/learn/learn-flask/simple-flask-heroku/venv/lib/python3.6/site-packages/jinja2/_compat.py", line 37, in reraise
    raise value.with_traceback(tb)
  File "/Users/clu/Development/learn/learn-flask/simple-flask-heroku/blogApp/templates/email/reset_password.txt", line 5, in top-level template code
    {{ url_for('reset_password', token=token, _external=True) }}
  File "/Users/clu/Development/learn/learn-flask/simple-flask-heroku/venv/lib/python3.6/site-packages/flask/helpers.py", line 356, in url_for
    return appctx.app.handle_url_build_error(error, endpoint, values)
  File "/Users/clu/Development/learn/learn-flask/simple-flask-heroku/venv/lib/python3.6/site-packages/flask/app.py", line 2061, in handle_url_build_error
    reraise(exc_type, exc_value, tb)
  File "/Users/clu/Development/learn/learn-flask/simple-flask-heroku/venv/lib/python3.6/site-packages/flask/_compat.py", line 35, in reraise
    raise value
  File "/Users/clu/Development/learn/learn-flask/simple-flask-heroku/venv/lib/python3.6/site-packages/flask/helpers.py", line 345, in url_for
    force_external=external)
  File "/Users/clu/Development/learn/learn-flask/simple-flask-heroku/venv/lib/python3.6/site-packages/werkzeug/routing.py", line 1776, in build
    raise BuildError(endpoint, values, method, self)
werkzeug.routing.BuildError: Could not build url for endpoint 'reset_password' with values ['token']. Did you mean 'reset_password_request' instead?
2019-01-10 13:07:14,695 INFO: Microblog startup [in /Users/clu/Development/learn/learn-flask/simple-flask-heroku/blogApp/__init__.py:49]
2019-01-10 13:08:08,827 INFO: Microblog startup [in /Users/clu/Development/learn/learn-flask/simple-flask-heroku/blogApp/__init__.py:49]
2019-01-10 13:08:28,144 ERROR: Exception on /reset_password_request [POST] [in /Users/clu/Development/learn/learn-flask/simple-flask-heroku/venv/lib/python3.6/site-packages/flask/app.py:1761]
Traceback (most recent call last):
  File "/Users/clu/Development/learn/learn-flask/simple-flask-heroku/venv/lib/python3.6/site-packages/flask/app.py", line 2292, in wsgi_app
    response = self.full_dispatch_request()
  File "/Users/clu/Development/learn/learn-flask/simple-flask-heroku/venv/lib/python3.6/site-packages/flask/app.py", line 1815, in full_dispatch_request
    rv = self.handle_user_exception(e)
  File "/Users/clu/Development/learn/learn-flask/simple-flask-heroku/venv/lib/python3.6/site-packages/flask/app.py", line 1718, in handle_user_exception
    reraise(exc_type, exc_value, tb)
  File "/Users/clu/Development/learn/learn-flask/simple-flask-heroku/venv/lib/python3.6/site-packages/flask/_compat.py", line 35, in reraise
    raise value
  File "/Users/clu/Development/learn/learn-flask/simple-flask-heroku/venv/lib/python3.6/site-packages/flask/app.py", line 1813, in full_dispatch_request
    rv = self.dispatch_request()
  File "/Users/clu/Development/learn/learn-flask/simple-flask-heroku/venv/lib/python3.6/site-packages/flask/app.py", line 1799, in dispatch_request
    return self.view_functions[rule.endpoint](**req.view_args)
  File "/Users/clu/Development/learn/learn-flask/simple-flask-heroku/blogApp/routes.py", line 180, in reset_password_request
    send_password_reset_email(user)
  File "/Users/clu/Development/learn/learn-flask/simple-flask-heroku/blogApp/email.py", line 21, in send_password_reset_email
    user=user, token=token))
  File "/Users/clu/Development/learn/learn-flask/simple-flask-heroku/blogApp/email.py", line 9, in send_email
    mail.send(msg)
  File "/Users/clu/Development/learn/learn-flask/simple-flask-heroku/venv/lib/python3.6/site-packages/flask_mail.py", line 491, in send
    with self.connect() as connection:
  File "/Users/clu/Development/learn/learn-flask/simple-flask-heroku/venv/lib/python3.6/site-packages/flask_mail.py", line 144, in __enter__
    self.host = self.configure_host()
  File "/Users/clu/Development/learn/learn-flask/simple-flask-heroku/venv/lib/python3.6/site-packages/flask_mail.py", line 165, in configure_host
    host.login(self.mail.username, self.mail.password)
  File "/anaconda3/lib/python3.6/smtplib.py", line 730, in login
    raise last_exception
  File "/anaconda3/lib/python3.6/smtplib.py", line 721, in login
    initial_response_ok=initial_response_ok)
  File "/anaconda3/lib/python3.6/smtplib.py", line 642, in auth
    raise SMTPAuthenticationError(code, resp)
smtplib.SMTPAuthenticationError: (535, b'5.7.8 Username and Password not accepted. Learn more at\n5.7.8  https://support.google.com/mail/?p=BadCredentials b73sm3331162itd.0 - gsmtp')
